Workbook

Sheet Main Page
A1: r
E2: TEST CASES
B5: Project Title | D5: Sta Rosa Payment Portal Phase 2 | H5: Project Manager | I5: Justin Orolfo
B6: Project Start Date | E6: Project End Date | H6: Project Client | I6: SMSGT
B8: Introduction
B9: This document outlines a set of test cases for Phase 2 of the City Government of Santa Rosa's Online Payment Portal. These test cases are derived from the Business Requirements Document (BRD) and Functional Requirements Document (FRD) and aim to verify that the new functionalities for the City Health Office (CHO I and II) and the Assessor’s Office meet the specified requirements and perform as expected
B11: Test Case Structure
B12: Each test case will follow the structure below:
B13: Test Case ID | G13: Unique identifier for the test case (e.g., TC-UI-001).
B14: Test Objective | G14: A clear statement of what is being tested.
B15: Preconditions | G15: Any prerequisites that must be met before executing the test case.
B16: Test Steps | G16: A detailed, step-by-step procedure to execute the test.
B17: Expected Result | G17: The anticipated outcome if the system is functioning correctly.
B18: Status | G18: (To be filled during testing: Pass/Fail/Blocked/N/A)
B19: Comments | G19: (Any relevant notes or observations during testing)

Sheet Dashboard
A3: Total Outstanding | B3: Status | C3: TOTAL | D3: PG-US-01 | E3: PG-US-02 | F3: PG-US-03 | G3: PG-US-04 | H3: PG-US-05 | I3: PG-US-06 | J3: PG-US-07 | K3: PG-US-08 | L3: PG-US-09 | M3: PG-US-10 | N3: PG-US-11 | O3: PG-US-12 | P3: PG-US-13 | Q3: PG-US-14 | R3: PG-US-15 | S3: PG-US-16 | T3: PG-US-17 | U3: AO-US-01 | V3: AO-US-02 | W3: AO-US-03
A4: =Sum(D4:T6) -> 404 | B4: OPEN | C4: =SUM(D4:T4) -> 366 | D4: =COUNTIF('PG-US-01'!F:F, "OPEN") -> 0 | E4: =COUNTIF('PG-US-02'!F:F, "OPEN") -> 0 | F4: =COUNTIF('PG-US-03'!F:F, "OPEN") -> 0 | G4: =COUNTIF('PG-US-04'!F:F, "OPEN") -> 0 | H4: =COUNTIF('PG-US-05'!F:F, "OPEN") -> 19 | I4: =COUNTIF('PG-US-06'!F:F, "OPEN") -> 16 | J4: =COUNTIF('PG-US-07'!F:F, "OPEN") -> 16 | K4: =COUNTIF('PG-US-08'!F:F, "OPEN") -> 16 | L4: =COUNTIF('PG-US-09'!F:F, "OPEN") -> 16 | M4: =COUNTIF('PG-US-10'!F:F, "OPEN") -> 0 | N4: =COUNTIF('PG-US-11'!F:F, "OPEN") -> 9 | O4: =COUNTIF('PG-US-12'!F:F, "OPEN") -> 63 | P4: =COUNTIF('PG-US-13'!F:F, "OPEN") -> 72 | Q4: =COUNTIF('PG-US-14'!F:F, "OPEN") -> 55 | R4: =COUNTIF('PG-US-15'!F:F, "OPEN") -> 13 | S4: =COUNTIF('PG-US-16'!F:F, "OPEN") -> 3 | T4: =COUNTIF('PG-US-17'!$F:$F, "OPEN") -> 68 | U4: =COUNTIF('AO-US-01'!$F:$F, "OPEN") -> 3 | V4: =COUNTIF('AO-US-02'!$F:$F, "OPEN") -> 105 | W4: =COUNTIF('AO-US-03'!$F:$F, "OPEN") -> 22
B5: FAILED | C5: =SUM(D5:T5) -> 37 | D5: =COUNTIF('PG-US-01'!F:F, "FAILED") -> 5 | E5: =COUNTIF('PG-US-02'!F:F, "FAILED") -> 2 | F5: =COUNTIF('PG-US-03'!F:F, "FAILED") -> 0 | G5: =COUNTIF('PG-US-04'!F:F, "FAILED") -> 0 | H5: =COUNTIF('PG-US-05'!F:F, "FAILED") -> 1 | I5: =COUNTIF('PG-US-06'!F:F, "FAILED") -> 1 | J5: =COUNTIF('PG-US-07'!F:F, "FAILED") -> 2 | K5: =COUNTIF('PG-US-08'!F:F, "FAILED") -> 2 | L5: =COUNTIF('PG-US-09'!F:F, "FAILED") -> 2 | M5: =COUNTIF('PG-US-10'!F:F, "FAILED") -> 14 | N5: =COUNTIF('PG-US-11'!F:F, "FAILED") -> 7 | O5: =COUNTIF('PG-US-12'!F:F, "FAILED") -> 0 | P5: =COUNTIF('PG-US-13'!F:F, "FAILED") -> 0 | Q5: =COUNTIF('PG-US-14'!F:F, "FAILED") -> 0 | R5: =COUNTIF('PG-US-15'!F:F, "FAILED") -> 1 | S5: =COUNTIF('PG-US-16'!F:F, "FAILED") -> 0 | T5: =COUNTIF('PG-US-17'!$F:$F, "FAILED") -> 0 | U5: =COUNTIF('AO-US-01'!$F:$F, "FAILED") -> 1 | V5: =COUNTIF('AO-US-02'!$F:$F, "FAILED") -> 17 | W5: =COUNTIF('AO-US-03'!$F:$F, "FAILED") -> 1
B6: BLOCKED | C6: =SUM(D6:T6) -> 1 | D6: =COUNTIF('PG-US-01'!F:F, "BLOCKED") -> 0 | E6: =COUNTIF('PG-US-02'!F:F, "BLOCKED") -> 1 | F6: =COUNTIF('PG-US-03'!F:F, "BLOCKED") -> 0 | G6: =COUNTIF('PG-US-04'!F:F, "BLOCKED") -> 0 | H6: =COUNTIF('PG-US-05'!F:F, "BLOCKED") -> 0 | I6: =COUNTIF('PG-US-06'!F:F, "BLOCKED") -> 0 | J6: =COUNTIF('PG-US-07'!F:F, "BLOCKED") -> 0 | K6: =COUNTIF('PG-US-08'!F:F, "BLOCKED") -> 0 | L6: =COUNTIF('PG-US-09'!F:F, "BLOCKED") -> 0 | M6: =COUNTIF('PG-US-10'!F:F, "BLOCKED") -> 0 | N6: =COUNTIF('PG-US-11'!F:F, "BLOCKED") -> 0 | O6: =COUNTIF('PG-US-12'!F:F, "BLOCKED") -> 0 | P6: =COUNTIF('PG-US-13'!F:F, "BLOCKED") -> 0 | Q6: =COUNTIF('PG-US-14'!F:F, "BLOCKED") -> 0 | R6: =COUNTIF('PG-US-15'!F:F, "BLOCKED") -> 0 | S6: =COUNTIF('PG-US-16'!F:F, "BLOCKED") -> 0 | T6: =COUNTIF('PG-US-17'!$F:$F, "BLOCKED") -> 0 | U6: =COUNTIF('AO-US-01'!$F:$F, "BLOCKED") -> 0 | V6: =COUNTIF('AO-US-02'!$F:$F, "BLOCKED") -> 0 | W6: =COUNTIF('AO-US-03'!$F:$F, "BLOCKED") -> 0
B7: PASSED | C7: =SUM(D7:T7) -> 378 | D7: =COUNTIF('PG-US-01'!F:F, "PASSED") -> 10 | E7: =COUNTIF('PG-US-02'!F:F, "PASSED") -> 12 | F7: =COUNTIF('PG-US-03'!F:F, "PASSED") -> 7 | G7: =COUNTIF('PG-US-04'!F:F, "PASSED") -> 9 | H7: =COUNTIF('PG-US-05'!F:F, "PASSED") -> 39 | I7: =COUNTIF('PG-US-06'!F:F, "PASSED") -> 44 | J7: =COUNTIF('PG-US-07'!F:F, "PASSED") -> 51 | K7: =COUNTIF('PG-US-08'!F:F, "PASSED") -> 59 | L7: =COUNTIF('PG-US-09'!F:F, "PASSED") -> 30 | M7: =COUNTIF('PG-US-10'!F:F, "PASSED") -> 47 | N7: =COUNTIF('PG-US-11'!F:F, "PASSED") -> 48 | O7: =COUNTIF('PG-US-12'!F:F, "PASSED") -> 0 | P7: =COUNTIF('PG-US-13'!F:F, "PASSED") -> 0 | Q7: =COUNTIF('PG-US-14'!F:F, "PASSED") -> 16 | R7: =COUNTIF('PG-US-15'!F:F, "PASSED") -> 5 | S7: =COUNTIF('PG-US-16'!F:F, "PASSED") -> 1 | T7: =COUNTIF('PG-US-17'!$F:$F, "PASSED") -> 0 | U7: =COUNTIF('AO-US-01'!$F:$F, "PASSED") -> 82 | V7: =COUNTIF('AO-US-02'!$F:$F, "PASSED") -> 49 | W7: =COUNTIF('AO-US-03'!$F:$F, "PASSED") -> 6
C9: ='PG-US-01'!$A$1 -> PG-US-01 | E9: ='PG-US-02'!$A$1 -> PG-US-02 | G9: ='PG-US-03'!$A$1 -> PG-US-03 | I9: ='PG-US-04'!$A$1 -> PG-US-04 | K9: ='PG-US-05'!$A$1 -> PG-US-05 | M9: ='PG-US-06'!$A$1 -> PG-US-06 | O9: ='PG-US-07'!$A$1 -> PG-US-07 | Q9: ='PG-US-08'!$A$1 -> PG-US-08 | S9: ='PG-US-09'!$A$1 -> PG-US-09 | U9: ='PG-US-10'!$A$1 -> PG-US-10 | W9: ='PG-US-11'!$A$1 -> PG-US-11 | Y9: ='PG-US-12'!$A$1 -> PG-US-12 | AA9: ='PG-US-13'!$A$1 -> PG-US-13 | AC9: ='PG-US-14'!$A$1 -> PG-US-14 | AE9: ='PG-US-15'!$A$1 -> PG-US-15 | AG9: ='PG-US-16'!$A$1 -> PG-US-16 | AI9: ='PG-US-17'!$A$1 -> PG-US-17 | AK9: ='AO-US-01'!$A$1 -> AO-US-01 | AM9: ='AO-US-02'!$A$1 -> AO-US-01 | AO9: ='AO-US-02'!$A$1 -> AO-US-01
A10: PROGRESS TRACKER | C10: ='PG-US-01'!B1 -> USER STORY: As a new user, I want to click the 'New? Sign Up' button on the login page so that I can access the registration form and create an account. | E10: ='PG-US-02'!B1 -> USER STORY: As a registered user of the Assessor’s Office portal, I want to log in using my email and password, So that I can access my personal records and services provided by the City of Sta. Rosa. | G10: ='PG-US-03'!B1 -> USER STORY: As a new user of the Assessor’s Office portal, I want to see a confirmation message after submitting my email for verification, So that I know the next steps and can return to the homepage easily. | I10: ='PG-US-04'!B1 -> USER STORY: As a logged-in user of the Assessor’s Office portal, I want to access my profile, logout option, see a welcome message, and submit new requests easily, So that I can efficiently manage my account and services. | K10: ='PG-US-05'!B1 -> USER STORY: As a property owner, I want to apply for a Certificate of True Copy of Tax Declaration So that I can process my property documentation And have it claimed as Personal | M10: ='PG-US-06'!B1 -> USER STORY: As a property owner, I want to apply for a Certificate of True Copy of Tax Declaration So that I can process my property documentation And have it claimed by an Authorized Representative on my behalf. | O10: ='PG-US-07'!B1 -> USER STORY: As a property owner, I want to apply for a Transfer of Tax Declaration So that I can process my property documentation And claim the certificate in Personal. | Q10: ='PG-US-08'!B1 -> USER STORY: As a property owner, I want to apply for a Transfer of Tax So that I can process my property documentation And claim the certificate by an Authorized Representative. | S10: ='PG-US-09'!B1 -> USER STORY: As a property owner, I want to apply for a Certificate of No-Property So that I can process my property documentation And claim the certificate in Personal. | U10: ='PG-US-10'!B1 -> USER STORY: As a property owner, I want to apply for a Certificate of No-Property So that I can process my property documentation And have it claimed by an Authorized Representative on my behalf. | W10: ='PG-US-11'!B1 -> USER STORY: As a property owner, I want to apply for a Certificate of Aggregate Landholdings So that I can process my property documentation And claim the certificate in Personal. | Y10: ='PG-US-12'!B1 -> USER STORY: As a property owner, I want to apply for a Certificate of Aggregate Landholdings So that I can process my property documentation And have it claimed by an Authorized Representative on my behalf. | AA10: ='PG-US-13'!B1 -> USER STORY: As a property owner, I want to apply for a Others Documents So that I can process my property documentation And claim the certificate in Personal. | AC10: ='PG-US-14'!B1 -> USER STORY: As a property owner, I want to apply for a Other Documents So that I can process my property documentation And have it claimed by an Authorized Representative on my behalf. | AE10: ='PG-US-15'!B1 -> USER STORY: DASHBOARD As a registered user, I want to view the list of my ongoing certificate applications with details like Ticket ID, status, amount, date, and upload/payment options, so that I can monitor the progress, fulfill missing requirements, make payments if applicable, and ensure my applications are processed smoothly. | AG10: ='PG-US-16'!B1 -> USER STORY: DASHBOARD As a registered user, I want to view my past certificate claims (History) with Ticket IDs, dates, and the list of claimed certificates using a year filter and search, so that I can access a full record of my completed applications for future reference or documentation. | AI10: ='PG-US-17'!B1 -> USER STORY: As a property owner, I want to apply for both the Certificate of True Copy of Tax Declaration and Transfer of Tax Declaration So that I can process my property documentation And claim it personally. | AK10: ='AO-US-01'!B1 -> USER STORY: As a system admistrator, I want to configure and edit email templates based on request status, So that the system can automatically send appropriate and customizable notifications to users at each stage of their certificate request. | AM10: ='AO-US-02'!B1 -> USER STORY: As a system administrator, I want to view, filter, and manage certificate requests submitted by applicants, So that I can monitor the status of each request, update records, and take appropriate actions such as editing or deleting submissions. | AO10: ='AO-US-03'!B1 -> USER STORY: As a system administrator, I want to configure and manage email notifications assigned to specific internal user groups and status types, So that the correct group (e.g., AO Officer, Treasury Office, BPLO Admin) receives automated updates or task reminders as certificate requests move through different statuses.
C11: Status | D11: Comment | E11: Status | F11: Comment | G11: Status | H11: Comment | I11: Status | J11: Comment | K11: Status | L11: Comment | M11: Status | N11: Comment | O11: Status | P11: Comment | Q11: Status | R11: Comment | S11: Status | T11: Comment | U11: Status | V11: Comment | W11: Status | X11: Comment | Y11: Status | Z11: Comment | AA11: Status | AB11: Comment | AC11: Status | AD11: Comment | AE11: Status | AF11: Comment | AG11: Status | AH11: Comment | AI11: Status | AJ11: Comment | AK11: Status | AL11: Comment | AM11: Status | AN11: Comment | AO11: Status | AP11: Comment
A12: US-TC-01 | C12: {='PG-US-01'!F3:F994} -> PASSED | D12: {='PG-US-01'!G3:G994} | E12: {='PG-US-02'!F3:F994} -> PASSED | F12: {='PG-US-02'!G3:G994} | G12: {='PG-US-03'!F3:F994} -> PASSED | H12: {='PG-US-03'!G3:G994} | I12: {='PG-US-04'!F3:F994} -> PASSED | J12: {='PG-US-04'!G3:G994} -> "type of certificate" field changed to drop down. comma text no longer applicable. multi select from drop down doesnt seem to be allowed but primary function working | K12: {='PG-US-05'!F3:F994} -> PASSED | L12: {='PG-US-05'!G3:G994} | M12: {='PG-US-06'!F3:F994} -> PASSED | N12: {='PG-US-06'!G3:G994} | O12: {='PG-US-07'!F3:F994} -> PASSED | P12: {='PG-US-07'!G3:G994} | Q12: {='PG-US-08'!F3:F994} -> PASSED | R12: {='PG-US-08'!G3:G994} | S12: {='PG-US-09'!F3:F994} -> PASSED | T12: {='PG-US-09'!G3:G994} | U12: {='PG-US-10'!F3:F994} -> PASSED | V12: {='PG-US-10'!G3:G994} | W12: {='PG-US-11'!F3:F994} -> PASSED | X12: {='PG-US-11'!G3:G994} | Y12: {='PG-US-12'!F3:F994} -> OPEN | Z12: {='PG-US-12'!G3:G994} | AA12: {='PG-US-13'!F3:F994} -> OPEN | AB12: {='PG-US-13'!G3:G994} | AC12: {='PG-US-14'!F3:F994} -> PASSED | AD12: {='PG-US-14'!G3:G994} | AE12: {='PG-US-15'!F3:F994} -> PASSED | AF12: {='PG-US-15'!G3:G994} | AG12: {='PG-US-16'!F3:F994} -> OPEN | AH12: {='PG-US-16'!G3:G994} | AI12: {='PG-US-17'!$F$3:$F994} -> OPEN | AJ12: {='PG-US-17'!$G$3:$G994} | AK12: {='AO-US-01'!$F$3:$F994} -> PASSED | AL12: {='AO-US-01'!$G$3:$G994} | AM12: {='AO-US-02'!$F$3:$F994} -> PASSED | AN12: {='AO-US-02'!$G$3:$G994} | AO12: {='AO-US-03'!$F$3:$F994} -> FAILED | AP12: {='AO-US-03'!$G$3:$G994} -> working - however there is no validation if the exact group and status is submitted as an already existing record
A13: US-TC-02 | C13: FAILED | D13: It accepts contact numbers that start with '09', but it also accepts inputs even if all the characters are not numeric. | E13: PASSED | G13: PASSED | I13: PASSED | K13: PASSED | M13: PASSED | O13: PASSED | Q13: PASSED | S13: PASSED | U13: PASSED | W13: PASSED | Y13: OPEN | AA13: OPEN | AC13: PASSED | AE13: PASSED | AG13: OPEN | AI13: OPEN | AK13: PASSED | AM13: PASSED | AN13: suggestion to match ticket ID with user portal's ticket ID | AO13: PASSED
A14: US-TC-03 | C14: FAILED | D14: It accepts contact numbers that start with '639', but it also accepts inputs even if all the characters are not numeric. | E14: PASSED | G14: PASSED | I14: PASSED | K14: PASSED | M14: PASSED | O14: PASSED | Q14: PASSED | S14: PASSED | U14: PASSED | W14: PASSED | Y14: OPEN | AA14: OPEN | AC14: PASSED | AE14: PASSED | AG14: OPEN | AH14: works and displays "No data available in table" but if there is no data to be shown, does the year filter drop down become disabled/unclickable? if the drop down only visible IF there's records in the history database? | AI14: OPEN | AK14: PASSED | AM14: PASSED | AO14: PASSED
A15: US-TC-04 | C15: PASSED | E15: PASSED | G15: PASSED | I15: PASSED | K15: PASSED | M15: PASSED | O15: PASSED | Q15: PASSED | S15: PASSED | U15: PASSED | W15: PASSED | Y15: OPEN | AA15: OPEN | AC15: PASSED | AE15: PASSED | AG15: PASSED | AI15: OPEN | AK15: PASSED | AM15: PASSED | AO15: PASSED
A16: US-TC-05 | C16: PASSED | E16: PASSED | G16: PASSED | I16: PASSED | K16: PASSED | M16: PASSED | O16: PASSED | Q16: PASSED | S16: PASSED | U16: PASSED | W16: PASSED | Y16: OPEN | AA16: OPEN | AC16: PASSED | AE16: PASSED | AI16: OPEN | AK16: PASSED | AM16: PASSED | AO16: PASSED
A17: US-TC-06 | C17: PASSED | E17: FAILED | F17: triggers T&C validation but button does not disable | G17: PASSED | I17: PASSED | J17: allows me to select future dates past current date | K17: PASSED | M17: PASSED | O17: PASSED | Q17: PASSED | S17: PASSED | U17: PASSED | W17: PASSED | Y17: OPEN | AA17: OPEN | AC17: PASSED | AE17: FAILED | AF17: working - however, email received display the ticket ID system of CMS which does not correspond to the ticket ID shown to users, potentially creating confusion whenever getting email notifications setting this to "failed' status to bring this detail to attention | AI17: OPEN | AK17: PASSED | AM17: PASSED | AO17: PASSED
A18: US-TC-07 | C18: PASSED | E18: PASSED | G18: PASSED | I18: PASSED | K18: PASSED | M18: PASSED | O18: PASSED | Q18: PASSED | S18: PASSED | U18: PASSED | W18: PASSED | Y18: OPEN | AA18: OPEN | AC18: PASSED | AE18: OPEN | AI18: OPEN | AK18: PASSED | AM18: PASSED | AO18: PASSED
A19: US-TC-08 | C19: PASSED | E19: PASSED | I19: PASSED | K19: PASSED | M19: PASSED | O19: PASSED | Q19: PASSED | S19: PASSED | U19: PASSED | W19: PASSED | Y19: OPEN | AA19: OPEN | AC19: PASSED | AE19: OPEN | AI19: OPEN | AK19: PASSED | AM19: OPEN | AO19: OPEN
A20: US-TC-09 | C20: PASSED | E20: PASSED | I20: PASSED | K20: PASSED | M20: PASSED | O20: PASSED | Q20: PASSED | S20: PASSED | U20: PASSED | W20: PASSED | Y20: OPEN | AA20: OPEN | AC20: PASSED | AE20: OPEN | AI20: OPEN | AK20: PASSED | AM20: PASSED | AO20: OPEN
A21: US-TC-10 | C21: PASSED | E21: BLOCKED | K21: PASSED | M21: PASSED | O21: PASSED | Q21: PASSED | S21: PASSED | U21: PASSED | W21: PASSED | X21: only tested with invalid format but unable to test "unreadable/corrupted" | Y21: OPEN | AA21: OPEN | AC21: PASSED | AE21: OPEN | AI21: OPEN | AK21: PASSED | AM21: PASSED | AN21: export feature not found Hannah: The export feature is located below the table. edit: noted thank you | AO21: OPEN
A22: US-TC-11 | C22: PASSED | E22: PASSED | K22: PASSED | M22: PASSED | O22: PASSED | Q22: PASSED | S22: PASSED | U22: PASSED | W22: PASSED | Y22: OPEN | AA22: OPEN | AC22: PASSED | AE22: OPEN | AI22: OPEN | AK22: PASSED | AM22: PASSED | AO22: OPEN
A23: US-TC-12 | C23: FAILED | D23: validation is displayed only if submitted without following certain requirements. will only show them one by one and not simultaneously | E23: PASSED | K23: PASSED | M23: PASSED | O23: PASSED | Q23: PASSED | S23: PASSED | U23: PASSED | W23: PASSED | Y23: OPEN | AA23: OPEN | AC23: PASSED | AE23: OPEN | AI23: OPEN | AK23: PASSED | AM23: PASSED | AO23: OPEN
A24: US-TC-13 | C24: FAILED | D24: feature not implemented or N/A | E24: FAILED | F24: N/A or feature not implemented | K24: PASSED | M24: PASSED | O24: PASSED | Q24: PASSED | S24: PASSED | U24: PASSED | W24: PASSED | Y24: OPEN | AA24: OPEN | AC24: PASSED | AE24: OPEN | AI24: OPEN | AK24: PASSED | AM24: PASSED | AO24: OPEN
A25: US-TC-14 | C25: PASSED | D25: validation not triggered when submitting with only letters | E25: PASSED | K25: PASSED | M25: PASSED | O25: PASSED | Q25: PASSED | S25: PASSED | U25: PASSED | W25: PASSED | Y25: OPEN | AA25: OPEN | AC25: PASSED | AE25: OPEN | AI25: OPEN | AK25: PASSED | AM25: PASSED | AO25: OPEN
A26: US-TC-15 | C26: FAILED | D26: validation not triggered when submitting with future date | E26: PASSED | K26: PASSED | M26: PASSED | O26: PASSED | Q26: PASSED | S26: PASSED | U26: PASSED | W26: PASSED | Y26: OPEN | AA26: OPEN | AC26: PASSED | AE26: OPEN | AI26: OPEN | AK26: PASSED | AM26: PASSED | AO26: OPEN
A27: US-TC-16 | K27: PASSED | M27: PASSED | O27: PASSED | Q27: PASSED | S27: PASSED | U27: PASSED | W27: PASSED | Y27: OPEN | AA27: OPEN | AC27: PASSED | AE27: OPEN | AI27: OPEN | AK27: PASSED | AM27: PASSED | AO27: OPEN
A28: US-TC-17 | K28: PASSED | M28: PASSED | O28: PASSED | Q28: PASSED | S28: PASSED | U28: PASSED | W28: PASSED | Y28: OPEN | AA28: OPEN | AC28: OPEN | AE28: OPEN | AI28: OPEN | AK28: PASSED | AM28: PASSED | AO28: OPEN
A29: US-TC-18 | K29: PASSED | M29: PASSED | O29: PASSED | Q29: PASSED | S29: PASSED | U29: PASSED | W29: PASSED | Y29: OPEN | AA29: OPEN | AC29: OPEN | AE29: OPEN | AI29: OPEN | AK29: PASSED | AM29: OPEN | AN29: currently no record long enough to check at the moment | AO29: OPEN
A30: US-TC-19 | K30: PASSED | M30: PASSED | O30: PASSED | Q30: PASSED | S30: PASSED | U30: PASSED | W30: PASSED | Y30: OPEN | AA30: OPEN | AC30: OPEN | AE30: OPEN | AI30: OPEN | AK30: PASSED | AM30: OPEN | AN30: file fields are disabled even if draft status? | AO30: OPEN
A31: US-TC-20 | K31: PASSED | M31: PASSED | O31: PASSED | Q31: PASSED | S31: PASSED | U31: PASSED | W31: PASSED | Y31: OPEN | AA31: OPEN | AC31: OPEN | AI31: OPEN | AK31: PASSED | AM31: FAILED | AN31: page crashes when attempting to change status to "certificate claimed" BadMethodCallException Call to undefined method App\Models\Certificate::getCertificateTypeText() | AO31: OPEN
A32: US-TC-21 | K32: PASSED | M32: PASSED | O32: PASSED | Q32: PASSED | S32: PASSED | U32: PASSED | W32: PASSED | Y32: OPEN | AA32: OPEN | AC32: OPEN | AI32: OPEN | AK32: PASSED | AM32: PASSED | AO32: OPEN
A33: US-TC-22 | K33: PASSED | M33: PASSED | O33: PASSED | Q33: PASSED | S33: PASSED | U33: PASSED | W33: PASSED | Y33: OPEN | AA33: OPEN | AC33: OPEN | AI33: OPEN | AK33: PASSED | AM33: PASSED | AO33: OPEN
A34: US-TC-23 | K34: PASSED | M34: PASSED | O34: PASSED | Q34: PASSED | S34: PASSED | U34: PASSED | W34: PASSED | Y34: OPEN | AA34: OPEN | AC34: OPEN | AI34: OPEN | AK34: PASSED | AM34: PASSED | AO34: OPEN
A35: US-TC-24 | K35: PASSED | M35: PASSED | O35: PASSED | Q35: PASSED | S35: PASSED | U35: PASSED | W35: PASSED | Y35: OPEN | AA35: OPEN | AC35: OPEN | AI35: OPEN | AK35: PASSED | AM35: PASSED | AO35: OPEN
A36: US-TC-25 | K36: PASSED | M36: PASSED | O36: PASSED | Q36: PASSED | S36: PASSED | U36: PASSED | W36: PASSED | Y36: OPEN | AA36: OPEN | AC36: OPEN | AI36: OPEN | AK36: PASSED | AM36: FAILED | AN36: "certificate claimed" affected by page breaking from bug | AO36: OPEN
A37: US-TC-26 | K37: PASSED | M37: PASSED | O37: PASSED | Q37: PASSED | S37: PASSED | U37: PASSED | W37: PASSED | Y37: OPEN | AA37: OPEN | AC37: OPEN | AI37: OPEN | AK37: PASSED | AM37: FAILED | AN37: note field working - however entered text does not reflect in email sent to requestor | AO37: OPEN
A38: US-TC-27 | K38: PASSED | M38: PASSED | O38: PASSED | Q38: PASSED | S38: PASSED | U38: PASSED | W38: PASSED | Y38: OPEN | AA38: OPEN | AC38: OPEN | AI38: OPEN | AK38: PASSED | AM38: PASSED | AO38: OPEN
A39: US-TC-28 | K39: PASSED | M39: PASSED | O39: PASSED | Q39: PASSED | S39: PASSED | U39: PASSED | W39: PASSED | Y39: OPEN | AA39: OPEN | AC39: OPEN | AI39: OPEN | AK39: PASSED | AM39: PASSED | AO39: OPEN
A40: US-TC-29 | K40: PASSED | M40: PASSED | O40: PASSED | Q40: PASSED | S40: PASSED | U40: PASSED | W40: PASSED | Y40: OPEN | AA40: OPEN | AC40: OPEN | AI40: OPEN | AK40: PASSED | AM40: PASSED | AO40: OPEN
A41: US-TC-30 | K41: PASSED | M41: PASSED | O41: PASSED | Q41: PASSED | S41: PASSED | U41: PASSED | W41: PASSED | Y41: OPEN | AA41: OPEN | AC41: OPEN | AI41: OPEN | AK41: PASSED | AM41: PASSED
A42: US-TC-31 | K42: PASSED | M42: PASSED | O42: PASSED | Q42: PASSED | S42: FAILED | T42: primary function to save draft is working "failed" - however there was no confirmation message displayed, only redirect to dashboard unless "confirmation message" = status update? correct status displayed | U42: PASSED | W42: PASSED | Y42: OPEN | AA42: OPEN | AC42: OPEN | AI42: OPEN | AK42: FAILED | AM42: PASSED
A43: US-TC-32 | K43: PASSED | M43: PASSED | O43: PASSED | Q43: PASSED | S43: FAILED | T43: primary function to submit application working "failed" - however there was no confirmation message displayed, only redirect to dashboard unless "confirmation message" = status update? correct status displayed | U43: PASSED | W43: PASSED | Y43: OPEN | AA43: OPEN | AC43: OPEN | AI43: OPEN | AK43: PASSED | AM43: PASSED
...

Sheet PG-US-01
A1: PG-US-01 | B1: USER STORY: As a new user, I want to click the 'New? Sign Up' button on the login page so that I can access the registration form and create an account.
A2: Test Case ID | B2: Test Objective | C2: Preconditions | D2: Test Steps | E2: Expected Results | F2: Status | G2: Comments/Issue
A3: =IF(B3<>"", "US-1-TC-" & TEXT(COUNTA($B$3:B3), "00"), "") -> US-1-TC-01 | B3: Verify that clicking the 'New? Sign Up' button on the Login page redirects the user to the Registration Form of the Assessor’s Office. | C3: 1. User must be on the Sta. Rosa Payroll Portal. 2. User must be on the Login page. | D3: 1. Search Assessor office login | E3: The registration form is displayed with the following required fields marked with an asterisk (*) and appropriate placeholders or labels: A note is shown: “Please fill out the fields below with your information. All fields with asterisks (*) are required. a) First Name* b) Middle Name c) Last Name* d) Date of Birth (dd/mm/yyyy)* e) Contact Number* f) Email Address* g) New Password* h) Confirm Password* A checkbox for "I agree to the Terms & Conditions of the City of Sta Rosa" Click the Submit button for the creation of account. | F3: PASSED
A4: =IF(B4<>"", "US-1-TC-" & TEXT(COUNTA($B$3:B4), "00"), "") -> US-1-TC-02 | B4: Verify that the system accepts a valid contact number that starts with '09' in the Contact Number field. | C4: 1. User must be on the Sta. Rosa Payroll Portal. 2. User must be on the Login page. 3. User must click the "New Sign-up" button. | D4: 1. Search Assessor office login 2. Click the "New?Sign up" button below the forget password. 3. Fill out the First Name Field 4. Fill out Middle Name Field 5. Fill out the Last Name Field 6. Fill out the Date of Birth 7. Fill out the Contact Number by 09 8. Fill out the Email Address Field 9. Set the Password on the New Password Field 10. Confirm the Password on the Confirm Password Field 11. Click the checkbox on T&C 12. Click Submit Button | E4: The registration form is displayed with the following required fields marked with an asterisk (*) and appropriate placeholders or labels: A note is shown: “Please fill out the fields below with your information. All fields with asterisks (*) are required. a) First Name* b) Middle Name c) Last Name* d) Date of Birth (dd/mm/yyyy)* e) Contact Number* f) Email Address* g) New Password* h) Confirm Password* A checkbox for "I agree to the Terms & Conditions of the City of Sta Rosa" Click the Submit button for the creation of account. After that it will go the Assessor Office confirmation message This confirmation message consist of the message: Assessor’s Office Thank you! Please check your e-mail inbox for verification. [Back to Home] button | F4: FAILED | G4: It accepts contact numbers that start with '09', but it also accepts inputs even if all the characters are not numeric.
A5: =IF(B5<>"", "US-1-TC-" & TEXT(COUNTA($B$3:B5), "00"), "") -> US-1-TC-03 | B5: Verify that the system accepts a valid contact number that starts with '639' in the Contact Number field. | C5: 1. User must be on the Sta. Rosa Payroll Portal. 2. User must be on the Login page. 3. User must click the "New Sign-up" button. | D5: 1. Search Assessor office login 2. Click the "New?Sign up" button below the forget password. 3. Fill out the First Name Field 4. Fill out Middle Name Field 5. Fill out the Last Name Field 6. Fill out the Date of Birth 7. Fill out the Contact Number by 639 8. Fill out the Email Address Field 9. Set the Password on the New Password Field 10. Confirm the Password on the Confirm Password Field 11. Click the checkbox on T&C 12. Click Submit Button | E5: The registration form is displayed with the following required fields marked with an asterisk (*) and appropriate placeholders or labels: A note is shown: “Please fill out the fields below with your information. All fields with asterisks (*) are required. a) First Name* b) Middle Name c) Last Name* d) Date of Birth (dd/mm/yyyy)* e) Contact Number* f) Email Address* g) New Password* h) Confirm Password* A checkbox for "I agree to the Terms & Conditions of the City of Sta Rosa" Click the Submit button for the creation of account. After that it will go the Assessor Office confirmation message This confirmation message consist of the message: Assessor’s Office Thank you! Please check your e-mail inbox for verification. [Back to Home] button | F5: FAILED | G5: It accepts contact numbers that start with '639', but it also accepts inputs even if all the characters are not numeric.
A6: =IF(B6<>"", "US-1-TC-" & TEXT(COUNTA($B$3:B6), "00"), "") -> US-1-TC-04 | B6: Verify that the system accepts a properly formatted email address (e.g., juandela@cruz.com) in the Email field. | C6: 1. User must be on the Sta. Rosa Payroll Portal. 2. User must be on the Login page. 3. User must click the "New Sign-up" button. | D6: 1. Search Assessor office login 2. Click the "New?Sign up" button below the forget password. 3. Fill out the First Name Field 4. Fill out Middle Name Field 5. Fill out the Last Name Field 6. Fill out the Date of Birth 7. Fill out the Contact Number 8. Fill out the Email Address Field with a valid email address "@" 9. Set the Password on the New Password Field 10. Confirm the Password on the Confirm Password Field 11. Click the checkbox on T&C 12. Click Submit Button | E6: The registration form is displayed with the following required fields marked with an asterisk (*) and appropriate placeholders or labels: A note is shown: “Please fill out the fields below with your information. All fields with asterisks (*) are required. a) First Name* b) Middle Name c) Last Name* d) Date of Birth (dd/mm/yyyy)* e) Contact Number* f) Email Address* g) New Password* h) Confirm Password* A checkbox for "I agree to the Terms & Conditions of the City of Sta Rosa" Click the Submit button for the creation of account. After that it will go the Assessor Office confirmation message This confirmation message consist of the message: Assessor’s Office Thank you! Please check your e-mail inbox for verification. [Back to Home] button | F6: PASSED
A7: =IF(B7<>"", "US-1-TC-" & TEXT(COUNTA($B$3:B7), "00"), "") -> US-1-TC-05 | B7: Verify that the system prevents form submission and displays an error when an invalid email address (e.g., juandelacruz) is entered. | C7: 1. User must be on the Sta. Rosa Payroll Portal. 2. User must be on the Login page. 3. User must click the "New Sign-up" button. | D7: 1. Search Assessor office login 2. Click the "New?Sign up" button below the forget password. 3. Fill out the First Name Field 4. Fill out Middle Name Field 5. Fill out the Last Name Field 6. Fill out the Date of Birth 7. Fill out the Contact Number 8. Fill out the Email Address Field with a valid email address "@" 9. Set the Password on the New Password Field 10. Confirm the Password on the Confirm Password Field 11. Click the checkbox on T&C 12. Click Submit Button | E7: An error message will be displayed if the email entered is invalid. | F7: PASSED
A8: =IF(B8<>"", "US-1-TC-" & TEXT(COUNTA($B$3:B8), "00"), "") -> US-1-TC-06 | B8: Verify that the system accepts a strong password that includes special characters or alphanumeric combinations. | C8: 1. User must be on the Sta. Rosa Payroll Portal. 2. User must be on the Login page. 3. User must click the "New Sign-up" button. | D8: 1. Search Assessor office login 2. Click the ""New?Sign up"" button below the forget password. 3. Fill out the First Name Field 4. Fill out Middle Name Field 5. Fill out the Last Name Field 6. Fill out the Date of Birth 7. Fill out the Contact Number 8. Fill out the Email Address Field 9. Set the Password on the New Password Field with special characters or strings 10. Confirm the Password on the Confirm Password Field 11. Click the checkbox on T&C 12. Click Submit Button | E8: The registration form is displayed with the following required fields marked with an asterisk (*) and appropriate placeholders or labels: A note is shown: “Please fill out the fields below with your information. All fields with asterisks (*) are required. a) First Name* b) Middle Name c) Last Name* d) Date of Birth (dd/mm/yyyy)* e) Contact Number* f) Email Address* g) New Password* h) Confirm Password* A checkbox for "I agree to the Terms & Conditions of the City of Sta Rosa" Click the Submit button for the creation of account. After that it will go the Assessor Office confirmation message This confirmation message consist of the message: Assessor’s Office Thank you! Please check your e-mail inbox for verification. [Back to Home] button | F8: PASSED
A9: =IF(B9<>"", "US-1-TC-" & TEXT(COUNTA($B$3:B9), "00"), "") -> US-1-TC-07 | B9: Verify that the system prevents form submission when the Confirm Password field does not match the New Password field. | C9: 1. User must be on the Sta. Rosa Payroll Portal. 2. User must be on the Login page. 3. User must click the "New Sign-up" button. | D9: 1. Search Assessor office login 2. Click the ""New?Sign up"" button below the forget password. 3. Fill out the First Name Field 4. Fill out Middle Name Field 5. Fill out the Last Name Field 6. Fill out the Date of Birth 7. Fill out the Contact Number 8. Fill out the Email Address Field 9. Set the Password on the New Password Field with special characters or strings 10. Confirm the Password with wrong characteds on the Confirm Password Field | E9: The user will receive a inline field warning if the confirmation password does not match the original password | F9: PASSED
A10: =IF(B10<>"", "US-1-TC-" & TEXT(COUNTA($B$3:B10), "00"), "") -> US-1-TC-08 | B10: Verify that the Submit button will not proceed if the Terms & Conditions checkbox is not checked. | C10: 1. User must be on the Sta. Rosa Payroll Portal. 2. User must be on the Login page. 3. User must click the "New Sign-up" button. | D10: 1. Search Assessor office login 2. Click the ""New?Sign up"" button below the forget password. 3. Fill out the First Name Field 4. Fill out Middle Name Field 5. Fill out the Last Name Field 6. Fill out the Date of Birth 7. Fill out the Contact Number 8. Fill out the Email Address Field 9. Set the Password on the New Password Field with special characters or strings 10. Confirm the Password on the Confirm Password Field 11. Click the checkbox on T&C 12. Click Submit Button | E10: Will received a pop up warning that the checkbox of T&C is not yet check. Should no proceed it not. | F10: PASSED
A11: =IF(B11<>"", "US-1-TC-" & TEXT(COUNTA($B$3:B11), "00"), "") -> US-1-TC-09 | B11: Verify that the Assessor’s Office Registration form displays required field validation messages when any mandatory field is left unanswered. | C11: 1. User must be on the Sta. Rosa Payroll Portal. 2. User must be on the Login page. 3. User must click the "New Sign-up" button. | D11: 1. Search Assessor office login 2. Click the ""New?Sign up"" button below the forget password. 3. Fill out the First Name Field 4. Fill out Middle Name Field 5. Fill out the Last Name Field 6. Fill out the Date of Birth 7. Fill out the Contact Number 8. Fill out the Email Address Field 9. Set the Password on the New Password Field with special characters or strings 10. Confirm the Password on the Confirm Password Field 11. Click the checkbox on T&C 12. Click Submit Button | E11: The registration form is displayed with the following required fields marked with an asterisk (*) and appropriate placeholders or labels: A note is shown: “Please fill out the fields below with your information. All fields with asterisks (*) are required. a) First Name* b) Middle Name c) Last Name* d) Date of Birth (dd/mm/yyyy)* e) Contact Number* f) Email Address* g) New Password* h) Confirm Password* A checkbox for "I agree to the Terms & Conditions of the City of Sta Rosa" Click the Submit button for the creation of account. After that it will go the Assessor Office confirmation message This confirmation message consist of the message: Assessor’s Office Thank you! Please check your e-mail inbox for verification. [Back to Home] button | F11: PASSED
A12: =IF(B12<>"", "US-1-TC-" & TEXT(COUNTA($B$3:B12), "00"), "") -> US-1-TC-10 | B12: Verifiy that after clicking the Registration button will be directed to Please Verify Login. | C12: 1. User must be on the Sta. Rosa Payroll Portal. 2. User must be on the Login page. 3. User must click the "New Sign-up" button. | F12: PASSED
A13: =IF(B13<>"", "US-1-TC-" & TEXT(COUNTA($B$3:B13), "00"), "") -> US-1-TC-11 | B13: Verify that clicking the 'Back to Home' button redirects the user to the Login page | C13: 1. User must be on the Sta. Rosa Payroll Portal. 2. User must be on the Login page. 3. User must click the "New Sign-up" button. | F13: PASSED
A14: =IF(B14<>"", "US-1-TC-" & TEXT(COUNTA($B$3:B14), "00"), "") -> US-1-TC-12 | B14: Verify that the password requirements are clearly indicated before any input is made. -Jed | C14: 1. User must be on the Sta. Rosa Payroll Portal. 2. User must be on the Login page. 3. User must click the "New Sign-up" button. | E14: The requirements, "Password must be at least 8 characters long and include at least one uppercase letter, one lowercase letter, one number, and one special character." Indicated clearly when creating a password. | F14: FAILED | G14: validation is displayed only if submitted without following certain requirements. will only show them one by one and not simultaneously
A15: =IF(B15<>"", "US-1-TC-" & TEXT(COUNTA($B$3:B15), "00"), "") -> US-1-TC-13 | B15: Verify that the password field in registration has a hide/show password toggle. -Jed | C15: 1. User must be on the Sta. Rosa Payroll Portal. 2. User must be on the Login page. 3. User must click the "New Sign-up" button. | E15: Password field having a button to toggle between hide and show. | F15: FAILED | G15: feature not implemented or N/A
A16: =IF(B16<>"", "US-1-TC-" & TEXT(COUNTA($B$3:B16), "00"), "") -> US-1-TC-14 | B16: Verify that the contact number field in registration won't allow alphabetic characters. -Jed | C16: 1. User must be on the Sta. Rosa Payroll Portal. 2. User must be on the Login page. 3. User must click the "New Sign-up" button. | E16: The system won't allow registration when the field for contact number contains letters. | F16: PASSED | G16: validation not triggered when submitting with only letters
A17: =IF(B17<>"", "US-1-TC-" & TEXT(COUNTA($B$3:B17), "00"), "") -> US-1-TC-15 | B17: Verify if the registration won't go through if the user's birth date is set in a future date. -Jed | C17: 1. User must be on the Sta. Rosa Payroll Portal. 2. User must be on the Login page. 3. User must click the "New Sign-up" button. | E17: The system won't allow registration when the user's birth date is beyond the current date. | F17: FAILED | G17: validation not triggered when submitting with future date

Sheet PG-US-02
A1: PG-US-02 | B1: USER STORY: As a registered user of the Assessor’s Office portal, I want to log in using my email and password, So that I can access my personal records and services provided by the City of Sta. Rosa.
A2: Test Case ID | B2: Test Objective | C2: Preconditions | D2: Test Steps | E2: Expected Results | F2: Status | G2: Comments
A3: =IF(B3<>"", "US-2-TC-" & TEXT(COUNTA($B$3:B3), "00"), "") -> US-2-TC-01 | B3: Verify that the login form loads correctly in the user interface. | C3: 1. User must be on the Sta. Rosa Payroll Portal. 2. User must be on the Login page. | D3: 1. Search Assessor office login 2. Navigate to the login page. | E3: The Assessor Office Login Page consists of the following elements: a) Email address field b) Password field c) Terms & Conditions checkbox d) Submit button e) Forgot Password link f) "New? Sign up" button | F3: PASSED
A4: =IF(B4<>"", "US-2-TC-" & TEXT(COUNTA($B$3:B4), "00"), "") -> US-2-TC-02 | B4: Verify that the system can able to log in using a registered email and password. | C4: 1. User must be on the Sta. Rosa Payroll Portal. 2. User must be on the Login page. | D4: 1. Search Assessor office login 2. Fill out the Email Address field with a registered email address 3. Fill out the Password field with a registered password 4. Click the checkbox of T&C 5. Click the Submit button | E4: After entering a registered email and password: a) Message is displayed: "Thank you!" "Please check your email inbox for verification." b) "Back to Home" button is shown. c) Clicking the "Back to Home" button redirects the user to the home page. After logging in with a verified new account, the user is redirected to the Assessor’s Office Dashboard, which includes the following elements: Assessor’s Office label a) Profile link b) Logout button Main Page Content: a) Welcome message for new accounts (e.g., “Welcome to the Assessor’s Office Portal!”) b) "New Request" button for submitting a new request | F4: PASSED
A5: =IF(B5<>"", "US-2-TC-" & TEXT(COUNTA($B$3:B5), "00"), "") -> US-2-TC-03 | B5: Verify that the system prevents to login when an invalid email is entered. | C5: 1. User must be on the Sta. Rosa Payroll Portal. 2. User must be on the Login page. | D5: 1. Search Assessor office login 2. Fill out the Email Address field with a invalid email address 3. Fill out the Password field 4. Click the checkbox of T&C 5. Click the Submit button | E5: The Assessor Office Login Page consists of the following elements: a) Email address field - Display an error message of "Please check your inputs, ensure that you input the same email address that you used upon registration, and your password is correct." b) Password field c) Terms & Conditions checkbox d) Submit button e) "New? Sign up" button f) Forgot Password link | F5: PASSED
A6: =IF(B6<>"", "US-2-TC-" & TEXT(COUNTA($B$3:B6), "00"), "") -> US-2-TC-04 | B6: Verify that the system prevents to login when an invalid password is entered. | C6: 1. User must be on the Sta. Rosa Payroll Portal. 2. User must be on the Login page. | D6: 1. Search Assessor office login 2. Fill out the Email Address field 3. Fill out the Password field with invalid password 4. Click the checkbox of T&C 5. Click the Submit button | E6: The Assessor Office Login Page consists of the following elements: a) Email address field - Display an error message of "Please check your inputs, ensure that you input the same email address that you used upon registration, and your password is correct." b) Password field c) Terms & Conditions checkbox d) Submit button e) "New? Sign up" button f) Forgot Password link | F6: PASSED
A7: =IF(B7<>"", "US-2-TC-" & TEXT(COUNTA($B$3:B7), "00"), "") -> US-2-TC-05 | B7: Verify that the system prevents to login when user is not registered. | C7: 1. User must be on the Sta. Rosa Payroll Portal. 2. User must be on the Login page. | D7: 1. Search Assessor office login 2. Fill out the Email Address field with a unregistered email address 3. Fill out the Password field with unregistered password 4. Click the checkbox of T&C 5. Click the Submit button | E7: The Assessor Office Login Page consists of the following elements: a) Email address field b) Password field c) Terms & Conditions checkbox d) Submit button e) Forgot Password link f) "New? Sign up" button - Display an error message of "Please check your inputs, ensure that you input the same email address that you used upon registration, and your password is correct." | F7: PASSED
A8: =IF(B8<>"", "US-2-TC-" & TEXT(COUNTA($B$3:B8), "00"), "") -> US-2-TC-06 | B8: Verify that the submit button is disabled when T&C is unchecked | C8: 1. User must be on the Sta. Rosa Payroll Portal. 2. User must be on the Login page. | D8: 1. Search Assessor office login 2. Fill out the Email Address field with a registered email address 3. Fill out the Password field 4. Do not click the checkbox of T&C 5. Click the Submit button | E8: The Assessor Office Login Page consists of the following elements: a) Email address field b) Password field c) Terms & Conditions checkbox d) Submit button e) Forgot Password link f) "New? Sign up" button - If the Terms & Conditions checkbox is not checked, a validation message appears: "Please accept the Terms & Conditions to proceed." | F8: FAILED | G8: triggers T&C validation but button does not disable
A9: =IF(B9<>"", "US-2-TC-" & TEXT(COUNTA($B$3:B9), "00"), "") -> US-2-TC-07 | B9: Verify that the system displays a required field when the Email, Password, or Terms & Conditions checkbox is left empty. | C9: 1. User must be on the Sta. Rosa Payroll Portal. 2. User must be on the Login page. | D9: 1. Search Assessor office login 2. Do not fill out the Email Address field 3. Do not fill out the Password field 4. Do not click the checkbox of T&C 5. Click the Submit button | E9: The Assessor Office Login Page consists of the following elements: a) Email address field b) Password field c) Terms & Conditions checkbox d) Submit button e) Forgot Password link f) "New? Sign up" button A required field validation message will appear if any of the following are left empty: i. Email address field: "The email field is required." or "The email must be a valid email address." ii. Password field: "The password field is required." iii. Terms & Conditions checkbox: "Please accept the Terms & Conditions to proceed." | F9: PASSED
A10: =IF(B10<>"", "US-2-TC-" & TEXT(COUNTA($B$3:B10), "00"), "") -> US-2-TC-08 | B10: Verify Forgot Password link navigates to reset page | C10: 1. User must be on the Sta. Rosa Payroll Portal. 2. User must be on the Login page. | D10: 1. Search Assessor office login 2. Click the Forgot Password link | E10: The Forgot Password page will have the following details: a) "A reset link will be sent to your email address." b) "Input your registered email address." c) Email Address field d) Send Password Reset Link button | F10: PASSED
A11: =IF(B11<>"", "US-2-TC-" & TEXT(COUNTA($B$3:B11), "00"), "") -> US-2-TC-09 | B11: Verify if the password requires at least one symbol, one lowercase letter, one uppercase letter, and one number | C11: 1. User must be on the Sta. Rosa Payroll Portal. 2. User must be on the Login page. | D11: 1. Search Assessor office login 2. Click the Forgot Password link | F11: PASSED
A12: =IF(B12<>"", "US-2-TC-" & TEXT(COUNTA($B$3:B12), "00"), "") -> US-2-TC-10 | B12: Able to submit the new password credentials even without meeting the required password security criteria | C12: 1. User must be on the Sta. Rosa Payroll Portal. 2. User must be on the Login page. | D12: 1. Search Assessor office login 2. Click the Forgot Password link | F12: BLOCKED
A13: =IF(B13<>"", "US-2-TC-" & TEXT(COUNTA($B$3:B13), "00"), "") -> US-2-TC-11 | B13: Verify that if the password and confirm password do not match, an appropriate error message is displayed | C13: 1. User must be on the Sta. Rosa Payroll Portal. 2. User must be on the Login page. | D13: 1. Search Assessor office login 2. Click the Forgot Password link | F13: PASSED
A14: =IF(B14<>"", "US-2-TC-" & TEXT(COUNTA($B$3:B14), "00"), "") -> US-2-TC-12 | B14: Verify that the user receives a reset password email after using the Forgot Password feature. | C14: 1. User must be on the Sta. Rosa Payroll Portal. 2. User must be on the Login page. | D14: 1. Search Assessor office login 2. Click the Forgot Password link | F14: PASSED
A15: =IF(B15<>"", "US-2-TC-" & TEXT(COUNTA($B$3:B15), "00"), "") -> US-2-TC-13 | B15: Verify that there is a toggle to show or hide the Password and Confirm Password fields. | C15: 1. User must be on the Sta. Rosa Payroll Portal. 2. User must be on the Login page. | D15: 1. Search Assessor office login 2. Click the Forgot Password link | F15: FAILED | G15: N/A or feature not implemented
A16: =IF(B16<>"", "US-2-TC-" & TEXT(COUNTA($B$3:B16), "00"), "") -> US-2-TC-14 | B16: Verify Sign Up link navigates to registration page | C16: 1. User must be on the Sta. Rosa Payroll Portal. 2. User must be on the Login page. | D16: 1. Search Assessor office login 2. Click the New?Sign up button | E16: The Assessor Office Login Page consists of the following elements: a) Email address field b) Password field c) Terms & Conditions checkbox d) Submit button e) Forgot Password link f) "New? Sign up" button The registration form is displayed with the following required fields marked with an asterisk (*) and appropriate placeholders or labels: A note is shown: “Please fill out the fields below with your information. All fields with asterisks (*) are required. a) First Name* b) Middle Name c) Last Name* d) Date of Birth (dd/mm/yyyy)* e) Contact Number* f) Email Address* g) New Password* h) Confirm Password* A checkbox for "I agree to the Terms & Conditions of the City of Sta Rosa" Click the Submit button for the creation of account. | F16: PASSED
A17: =IF(B17<>"", "US-2-TC-" & TEXT(COUNTA($B$3:B17), "00"), "") -> US-2-TC-15 | B17: Verify password input is masked | C17: 1. User must be on the Sta. Rosa Payroll Portal. 2. User must be on the Login page. | D17: 1. Search Assessor office login 2. Fill out the Email Address field with a registered email address 3. Fill out the Password field with a registered password | E17: The characters entered in the Password field should appear as masked characters (e.g., ••••••) | F17: PASSED

Sheet PG-US-03
A1: PG-US-03 | B1: USER STORY: As a new user of the Assessor’s Office portal, I want to see a confirmation message after submitting my email for verification, So that I know the next steps and can return to the homepage easily.
A2: Test Case ID | B2: Test Objective | C2: Preconditions | D2: Test Steps | E2: Expected Results | F2: Status | G2: Comments
A3: =IF(B3<>"", "US-3-TC-" & TEXT(COUNTA($B$4:B4), "00"), "") -> US-3-TC-01 | B3: Verify that the system sends a verification OTP email upon registration. | C3: 1. User must be on the Sta. Rosa Payroll Portal. 2. User must be on the Login page. | D3: 1. Search Assessor office login 2. Login with registered email and password and checkbox of T&C. 3. Click Submit button 4. Check OTP Verification sent on email. 5. Put the OTP on the Verification | E3: The user is redirected to a confirmation screen displaying the following: a) "Assessor’s Office" header b) "One-Time Passcode c) A message is displayed: "An email verification has been sent to your email address. Please click on the link within 15 minutes in order to proceed." d) An OTP input field labeled as "Input OTP Code" is shown. e) Didn't receive the OTP on your email address? text field below f) "Click here to resend" link for request OTP g) Submit button | F3: PASSED
A4: =IF(B4<>"", "US-3-TC-" & TEXT(COUNTA($B$4:B5), "00"), "") -> US-3-TC-02 | B4: Verify that the system sends a verification OTP email upon logging in. | C4: 1. User must be on the Sta. Rosa Payroll Portal. 2. User must be on the Login page. | D4: 1. Search Assessor office login 2. Login with registered email and password and checkbox of T&C. 3. Click Submit button 4. Check OTP Verification sent on email. 5. Put the OTP on the Verification | E4: The user is redirected to a confirmation screen displaying the following: a) "Assessor’s Office" header b) "One-Time Passcode c) A message is displayed: "An email verification has been sent to your email address. Please click on the link within 15 minutes in order to proceed." d) An OTP input field labeled as "Input OTP Code" is shown. e) Didn't receive the OTP on your email address? text field below f) "Click here to resend" link for request OTP g) Submit button | F4: PASSED
A5: =IF(B5<>"", "US-3-TC-" & TEXT(COUNTA($B$4:B6), "00"), "") -> US-3-TC-03 | B5: Verify that the user is able to enter a valid One-Time PIN (OTP) on the OTP verification page and is successfully redirected to the dashboard. | C5: 1. User must be on the Sta. Rosa Payroll Portal. 2. User must be on the Login page. | D5: 1. Search Assessor office login 2. Login with registered email and password and checkbox of T&C. 3. Click Submit button 4. Check OTP Verification sent on email. 5. Put the valid OTP on the Verification 6. Click submit or press enter | E5: The user is redirected to a confirmation screen displaying the following: a) "Assessor’s Office" header b) "One-Time Passcode c) A message is displayed: "An email verification has been sent to your email address. Please click on the link within 15 minutes in order to proceed." d) An OTP input field labeled as "Input OTP Code" is shown. e) Didn't receive the OTP on your email address? text field below f) "Click here to resend" link for request OTP g) Submit button | F5: PASSED
A6: =IF(B6<>"", "US-3-TC-" & TEXT(COUNTA($B$4:B7), "00"), "") -> US-3-TC-04 | B6: Verify that entering an invalid One-Time PIN (OTP) on the OTP verification page displays an error message. | C6: 1. User must be on the Sta. Rosa Payroll Portal. 2. User must be on the Login page. | D6: 1. Search Assessor office login 2. Login with registered email and password and checkbox of T&C. 3. Click Submit button 4. Check OTP Verification sent on email. 5. Put the invalid OTP on the Verification 6. Click submit or press enter | E6: The user is redirected to a confirmation screen displaying the following: a) "Assessor’s Office" header b) "One-Time Passcode c) A message is displayed: "An email verification has been sent to your email address. Please click on the link within 15 minutes in order to proceed." d) An OTP input field labeled as "Input OTP Code" is shown. e) Didn't receive the OTP on your email address? text field below f) "Click here to resend" link for request OTP g) Submit button | F6: PASSED
A7: =IF(B7<>"", "US-3-TC-" & TEXT(COUNTA($B$4:B8), "00"), "") -> US-3-TC-05 | B7: Verify that entering an expired One-Time PIN (OTP) after 15 minutes on the OTP verification page displays an error message indicating the OTP has expired. | C7: 1. User must be on the Sta. Rosa Payroll Portal. 2. User must be on the Login page. | D7: 1. Search Assessor office login 2. Login with registered email and password and checkbox of T&C. 3. Click Submit button 4. Check OTP Verification sent on email. 5. Put the expired OTP on the Verification 6. Click submit or press enter | E7: The user is redirected to a confirmation screen displaying the following: a) "Assessor’s Office" header b) "One-Time Passcode c) A message is displayed: "An email verification has been sent to your email address. Please click on the link within 15 minutes in order to proceed." d) An OTP input field labeled as "Input OTP Code" is shown. e) "Invalid verification code. Please try again." red text is shown below the field f) Didn't receive the OTP on your email address? text field below g) "Click here to resend" link for request OTP h) Submit button | F7: PASSED
A8: =IF(B8<>"", "US-3-TC-" & TEXT(COUNTA($B$4:B9), "00"), "") -> US-3-TC-06 | B8: Verify that a used OTP cannot be used again for verification on the OTP verification page. | C8: 1. User must be on the Sta. Rosa Payroll Portal. 2. User must be on the Login page. | D8: 1. Search Assessor office login 2. Login with registered email and password and checkbox of T&C. 3. Click Submit button 4. Click the Back to Home button | E8: Able to received an error message of "Invalid verification code. Please try again." | F8: PASSED
A9: =IF(B9<>"", "US-3-TC-" & TEXT(COUNTA($B$3:B10), "00"), "") -> US-3-TC-07 | B9: Verify that unable to request OTP if there is an existing OTP ongoing request. | C9: 1. User must be on the Sta. Rosa Payroll Portal. 2. User must be on the Login page. | D9: 1. Search Assessor office login 2. Login with registered email and password and checkbox of T&C. 3. Click Submit button 4. Click the Back to Home button | E9: The user is redirected to a confirmation screen displaying the following: a) "Assessor’s Office" header b) "One-Time Passcode c) A message is displayed: "An email verification has been sent to your email address. Please click on the link within 15 minutes in order to proceed." d) An OTP input field labeled as "Input OTP Code" is shown. e) "A One-Time PIN (OTP) has already been sent. Please wait 15 minutes before making another request." red text is shown below the field f) Didn't receive the OTP on your email address? text field below g) "Click here to resend" link for request OTP h) Submit button | F9: PASSED
A10: =IF(B10<>"", "US-3-TC-" & TEXT(COUNTA($B$3:B11), "00"), "")

Sheet PG-US-04
A1: PG-US-04 | B1: USER STORY: As a logged-in user of the Assessor’s Office portal, I want to access my profile, logout option, see a welcome message, and submit new requests easily, So that I can efficiently manage my account and services.
A2: Test Case ID | B2: Test Objective | C2: Preconditions | D2: Test Steps | E2: Expected Results | F2: Status | G2: Comments
A3: =IF(B3<>"", "US-4-TC-" & TEXT(COUNTA($B3:B$3), "00"), "") -> US-4-TC-01 | B3: Verify that clicking the "New Request" button redirects the user to the request of Certificate Application page. | C3: 1. User must be on the Sta. Rosa Payroll Portal. 2. User must be on the Login page. 3. User must be logged in 4. User must have successfully verified the One-Time PIN (OTP). 5. User must be on the New Request Page. | D3: 1. Search Assessor office login 2. Login with registered email and password and checkbox of T&C. 3. Have completed the OTP verification 4. Click the "New Request" button | E3: Certificate form should display all five checkbox options: a) Certificate of True Copy of Tax Declaration b) Transfer of Tax Declaration c) Certification of No-Property d) Certificate of Aggregate Landholdings e) Other Certifications - When user types into the "Type of Certificate" field, it should accept input with a popup guidance saying: “Put a comma between certificates. Example: Certificate A, Certificate B.” Claiming section should display two selectable options (radio buttons): a) Personal b) Authorized Representative c) "ID of Property Owner with 3 Signatures" w/ upload field button - field should allow drag-and-drop or file upload functionality. Accepted file types: .jpg, .png, .docx, .pdf Line separator Checkbox of I agree to the Terms & Condition of the City of the Sta Rosa Buttons (located the T&C): a) Save Changes — submits the form and saves the cretificate application b) Cancel — discards any changes and returns the user to the previous screen or dashboard | F3: PASSED | G3: "type of certificate" field changed to drop down. comma text no longer applicable. multi select from drop down doesnt seem to be allowed but primary function working
A4: =IF(B4<>"", "US-4-TC-" & TEXT(COUNTA($B$3:B4), "00"), "") -> US-4-TC-02 | B4: Verify that clicking the "Profile" link navigates the user to their profile details or account settings page. | C4: 1. User must be on the Sta. Rosa Payroll Portal. 2. User must be on the Login page. 3. User must be logged in 4. User must have successfully verified the One-Time PIN (OTP). 5. User must be on the New Request Page. | D4: 1. Search Assessor office login 2. Login with registered email and password and checkbox of T&C. 3. Have completed the OTP verification 4. Click the Profile link on the top right | E4: After the user is redirected to the Profile page, the screen should display the following layout and elements: Header: Assessor's Office Section: Profile a) First Name* — a text field is displayed below the label b) Middle Name — a text field is displayed below the label c) Last Name* — a text field is displayed below the label d) Date of Birth* — a text field is displayed below the label e) Contact Number* — a text field is displayed below the label f) E-mail Address — a text field is displayed below the label Line Separator Section: Password Update a) New Password* — a hashed password field is displayed below the label b) Confirm Password* — a hashed password field is displayed below the label Buttons (located below password fields): a) Save Changes — submits the form and saves the updated profile information b) Cancel — discards any changes and returns the user to the previous screen or dashboard | F4: PASSED
